Workbook

Sheet 표지
B2: B★ eCO₂ 소형 실용화 전략 보고서
B3: Chapter 1. 응용처 우선순위 & 재무 모델 보조표
B4: 한글판 (Korean Edition)
B7: 작성일 | D7: 2026-03-15
B8: 버전 | D8: v1.0 (B-1d)
B9: 문서 등급 | D9: 대외비
B10: 작성자 | D10: B★ 프로젝트 팀
B11: 기준 연도 | D11: 2026년
B14: 시트 구성
B16: ① | C16: 평가기준 | D16: 5개 평가기준 정의 및 가중치 — 수식으로 가중합계 자동산출
B17: ② | C17: 우선순위매트릭스 | D17: 6개 응용처 × 5기준 스코어링 — 수식으로 종합점수
B18: ③ | C18: 시장성장모델 | D18: 6개 응용처 × 2026-2035 CAGR 복리성장 수식
B19: ④ | C19: B★KPI시나리오 | D19: 보수/기본/낙관 3개 시나리오 — NPV·IRR·Payback 수식
B20: ⑤ | C20: 요약대시보드 | D20: 핵심 지표 자동 참조 요약
B23: 핵심 투자 수치
B25: IRR: 42.4% | C25: Payback: 4년 | D25: NPV: $81.7M
B26: CAPEX: $18M | C26: 10년 매출: $527M

Sheet 평가기준
A1: 기준ID | B1: 명칭 | C1: 가중치(%) | D1: 평가 내용 | E1: 비고
A2: C1 | B2: 매출조기성 | C2: 25 | D2: 매출 실현 속도 및 계약 파이프라인 선명도 (1-10점) | E2: 빠를수록 고점수
A3: C2 | B3: 기술적합도 | C3: 20 | D3: eCO₂ 기술의 해당 응용처 적합성 및 TRL 수준 (1-10점) | E3: TRL 7+ = 9점 이상
A4: C3 | B4: B★기술정합 | C4: 20 | D4: B★ eCO₂ 소형 모듈 아키텍처와의 직결 정도 (1-10점) | E4: 핵심 아키텍처 직결 = 10점
A5: C4 | B5: 정책지원도 | C5: 20 | D5: 한국 정부 정책·인허가·보조금 지원 강도 (1-10점) | E5: SMR법·DC정책 연계 고점수
A6: C5 | B6: CAGR정규화 | C6: 15 | D6: 해당 시장 CAGR 대비 정규화 점수 (CAGR 20%=10점 기준) | E6: 선형보간 적용
A7: 합계 | B7: — | C7: =SUM(C2:C6) | D7: 가중치 합계 = 100%
A9: CAGR 정규화 기준표
A10: CAGR 범위 | B10: 정규화 점수 | C10: 산출 방식
A11: 20% 이상 | B11: 10점 | C11: 기준점 (DC냉각 20.4%)
A12: 15% | B12: 8점 | C12: 선형보간
A13: 10% | B13: 6점 | C13: 선형보간
A14: 7% | B14: 5점 | C14: 선형보간
A15: 5% | B15: 4점 | C15: 최저 기준

Sheet 우선순위매트릭스
A1: 가중치 (참조) | C1: 25% | D1: 20% | E1: 20% | F1: 20% | G1: 15%
C2: 0.25 | D2: 0.2 | E2: 0.2 | F2: 0.2 | G2: 0.15
A3: 순위 | B3: 응용처 | C3: 매출조기성 (25%) | D3: 기술적합도 (20%) | E3: B★기술정합 (20%) | F3: 정책지원도 (20%) | G3: CAGR정규화 (15%) | H3: 가중합계 (수식) | I3: KR시장규모 ($M) | J3: CAGR (%) | K3: 종합점수 | L3: B★ 전략
A4: ★1 | B4: 데이터센터 냉각·폐열재생 | C4: 9.5 | D4: 9.8 | E4: 9.8 | F4: 9.2 | G4: 9.3 | H4: =C4*$C$2+D4*$D$2+E4*$E$2+F4*$F$2+G4*$G$2 | I4: 19900 | J4: 0.204 | K4: 9.35 | L4: 즉시 실행 (2026H2)
A5: ★2 | B5: 원전·SMR·열병합 연계 | C5: 8.2 | D5: 8.5 | E5: 8.8 | F5: 9 | G5: 8.7 | H5: =C5*$C$2+D5*$D$2+E5*$E$2+F5*$F$2+G5*$G$2 | I5: 4500 | J5: 0.18 | K5: 8.42 | L5: 중기 핵심 (2028+)
A6: 3 | B6: LNG 발전소 폐열발전 | C6: 7.5 | D6: 7.2 | E6: 7 | F6: 7.8 | G6: 6.2 | H6: =C6*$C$2+D6*$D$2+E6*$E$2+F6*$F$2+G6*$G$2 | I6: 3800 | J6: 0.085 | K6: 7.18 | L6: 중기 파이프라인
A7: 4 | B7: 산업 히트펌프(제철·석화) | C7: 6.8 | D7: 7 | E7: 6.5 | F7: 7.5 | G7: 5.8 | H7: =C7*$C$2+D7*$D$2+E7*$E$2+F7*$F$2+G7*$G$2 | I7: 8000 | J7: 0.079 | K7: 6.73 | L7: 정책 연계 R&D
A8: 5 | B8: 화력발전소 폐열회수 | C8: 6 | D8: 6.5 | E8: 6.2 | F8: 6.8 | G8: 5.2 | H8: =C8*$C$2+D8*$D$2+E8*$E$2+F8*$F$2+G8*$G$2 | I8: 3000 | J8: 0.065 | K8: 6.18 | L8: 전환 관찰
A9: 6 | B9: 제철소 고로 폐열 | C9: 5.5 | D9: 6 | E9: 5.8 | F9: 6.2 | G9: 4.8 | H9: =C9*$C$2+D9*$D$2+E9*$E$2+F9*$F$2+G9*$G$2 | I9: 2200 | J9: 0.06 | K9: 5.29 | L9: 장기 R&D (2030+)
A11: 통계 | C11: MAX | D11: MAX | E11: MAX | F11: MAX | G11: MAX | H11: MAX | I11: MAX | J11: MAX | K11: MAX
B12: 최대값 | C12: =MAX(C4:C9) | D12: =MAX(D4:D9) | E12: =MAX(E4:E9) | F12: =MAX(F4:F9) | G12: =MAX(G4:G9) | H12: =MAX(H4:H9) | I12: =MAX(I4:I9) | J12: =MAX(J4:J9) | K12: =MAX(K4:K9)
B13: 평균 | C13: =AVERAGE(C4:C9) | D13: =AVERAGE(D4:D9) | E13: =AVERAGE(E4:E9) | F13: =AVERAGE(F4:F9) | G13: =AVERAGE(G4:G9) | H13: =AVERAGE(H4:H9) | I13: =AVERAGE(I4:I9) | J13: =AVERAGE(J4:J9) | K13: =AVERAGE(K4:K9)

Sheet 시장성장모델
A1: 한국 목표시장 성장 모델 (2026-2035) ※ CAGR 복리성장 수식 적용
A2: 단위: $M (백만 달러) | 성장식: 기준연도 × (1+CAGR)^(연도-2026)
A3: 응용처 | B3: 2026E 기준($M) | C3: CAGR(%) | D3: 2026F | E3: 2027F | F3: 2028F | G3: 2029F | H3: 2030F | I3: 2031F | J3: 2032F | K3: 2033F | L3: 2034F | M3: 2035F | N3: 10yr CAGR 검증
A4: 데이터센터 냉각·폐열재생 | B4: 1990 | C4: 0.204 | D4: =B4 | E4: =$B4*(1+$C4)^1 | F4: =$B4*(1+$C4)^2 | G4: =$B4*(1+$C4)^3 | H4: =$B4*(1+$C4)^4 | I4: =$B4*(1+$C4)^5 | J4: =$B4*(1+$C4)^6 | K4: =$B4*(1+$C4)^7 | L4: =$B4*(1+$C4)^8 | M4: =$B4*(1+$C4)^9 | N4: =(M4/D4)^(1/9)-1
A5: 원전·SMR·열병합 연계 | B5: 380 | C5: 0.18 | D5: =B5 | E5: =$B5*(1+$C5)^1 | F5: =$B5*(1+$C5)^2 | G5: =$B5*(1+$C5)^3 | H5: =$B5*(1+$C5)^4 | I5: =$B5*(1+$C5)^5 | J5: =$B5*(1+$C5)^6 | K5: =$B5*(1+$C5)^7 | L5: =$B5*(1+$C5)^8 | M5: =$B5*(1+$C5)^9 | N5: =(M5/D5)^(1/9)-1
A6: LNG 발전소 폐열발전 | B6: 342 | C6: 0.085 | D6: =B6 | E6: =$B6*(1+$C6)^1 | F6: =$B6*(1+$C6)^2 | G6: =$B6*(1+$C6)^3 | H6: =$B6*(1+$C6)^4 | I6: =$B6*(1+$C6)^5 | J6: =$B6*(1+$C6)^6 | K6: =$B6*(1+$C6)^7 | L6: =$B6*(1+$C6)^8 | M6: =$B6*(1+$C6)^9 | N6: =(M6/D6)^(1/9)-1
A7: 산업 히트펌프(제철·석화) | B7: 3430 | C7: 0.079 | D7: =B7 | E7: =$B7*(1+$C7)^1 | F7: =$B7*(1+$C7)^2 | G7: =$B7*(1+$C7)^3 | H7: =$B7*(1+$C7)^4 | I7: =$B7*(1+$C7)^5 | J7: =$B7*(1+$C7)^6 | K7: =$B7*(1+$C7)^7 | L7: =$B7*(1+$C7)^8 | M7: =$B7*(1+$C7)^9 | N7: =(M7/D7)^(1/9)-1
A8: 화력발전소 폐열회수 | B8: 290 | C8: 0.065 | D8: =B8 | E8: =$B8*(1+$C8)^1 | F8: =$B8*(1+$C8)^2 | G8: =$B8*(1+$C8)^3 | H8: =$B8*(1+$C8)^4 | I8: =$B8*(1+$C8)^5 | J8: =$B8*(1+$C8)^6 | K8: =$B8*(1+$C8)^7 | L8: =$B8*(1+$C8)^8 | M8: =$B8*(1+$C8)^9 | N8: =(M8/D8)^(1/9)-1
A9: 제철소 고로 폐열 | B9: 215 | C9: 0.06 | D9: =B9 | E9: =$B9*(1+$C9)^1 | F9: =$B9*(1+$C9)^2 | G9: =$B9*(1+$C9)^3 | H9: =$B9*(1+$C9)^4 | I9: =$B9*(1+$C9)^5 | J9: =$B9*(1+$C9)^6 | K9: =$B9*(1+$C9)^7 | L9: =$B9*(1+$C9)^8 | M9: =$B9*(1+$C9)^9 | N9: =(M9/D9)^(1/9)-1
A10: 총합계(TAM) | B10: =SUM(B4:B9) | D10: =SUM(D4:D9) | E10: =SUM(E4:E9) | F10: =SUM(F4:F9) | G10: =SUM(G4:G9) | H10: =SUM(H4:H9) | I10: =SUM(I4:I9) | J10: =SUM(J4:J9) | K10: =SUM(K4:K9) | ... M10: =SUM(M4:M9)
A12: B★ SAM 추정 (DC냉각 시장 기준, 점유율 적용)
A13: 항목 | B13: 점유율 가정 | C13: CAGR | D13: 2026F | E13: 2027F | F13: 2028F | G13: 2029F | H13: 2030F | I13: 2031F | J13: 2032F | K13: 2033F | L13: 2034F | M13: 2035F | N13: 비고
A14: 보수 SAM (점유율 3%) | B14: 0.03 | D14: =D4*0.03 | E14: =E4*0.03 | F14: =F4*0.03 | G14: =G4*0.03 | H14: =H4*0.03 | I14: =I4*0.03 | J14: =J4*0.03 | K14: =K4*0.03 | ... M14: =M4*0.03 | N14: Hub-S1 매출 추정
A15: 기본 SAM (점유율 6%) | B15: 0.06 | D15: =D4*0.06 | E15: =E4*0.06 | F15: =F4*0.06 | G15: =G4*0.06 | H15: =H4*0.06 | I15: =I4*0.06 | J15: =J4*0.06 | K15: =K4*0.06 | ... M15: =M4*0.06 | N15: Hub-S1 매출 추정
A16: 낙관 SAM (점유율 10%) | B16: 0.1 | D16: =D4*0.1 | E16: =E4*0.1 | F16: =F4*0.1 | G16: =G4*0.1 | H16: =H4*0.1 | I16: =I4*0.1 | J16: =J4*0.1 | K16: =K4*0.1 | ... M16: =M4*0.1 | N16: Hub-S1 매출 추정

Sheet B★KPI시나리오
A1: B★ eCO₂ Hub-S1 KPI 시나리오 분석 (2026-2035)
A3: [ 투자 가정 — 입력값 (노란색 셀 직접 수정 가능) ]
A4: 항목 | B4: 단위 | C4: 보수 | D4: 기본 | E4: 낙관 | F4: 비고
A5: 초기 CAPEX (Hub-S1) | B5: $M | C5: 18 | D5: 18 | E5: 18 | F5: 1호기 DC냉각 모듈 고정
A6: 연간 운영비 (OPEX) | B6: $M/yr | C6: 1.8 | D6: 1.5 | E6: 1.2 | F6: CAPEX의 10%/8%/7%
A7: 연간 매출 성장률 (1-5년) | B7: % | C7: 25 | D7: 35 | E7: 50 | F7: DC냉각 파이프라인 확대
A8: 연간 매출 성장률 (6-10년) | B8: % | C8: 15 | D8: 22 | E8: 35 | F8: SMR·LNG 파이프라인 추가
A9: 기준연도 매출 (2026) | B9: $M | C9: 8 | D9: 12 | E9: 18 | F9: PoC 계약 수 기반
A10: 할인율 (WACC) | B10: % | C10: 12 | D10: 10 | E10: 8 | F10: B★ 리스크 프리미엄
A11: 법인세율 | B11: % | C11: 25 | D11: 22 | E11: 20 | F11: 한국 법인세 기준
A12: 잔존가치 (10년) | B12: $M | C12: 30 | D12: 45 | E12: 60 | F12: 기술·고객 자산 평가
A14: [ 연도별 매출 추정 ($M) — 수식 자동산출 ]
A15: 연도 | B15: 시나리오 | C15: 매출($M) | D15: 누적매출($M) | E15: YoY성장률 | F15: 비고
A46: 2026 | B46: 보수 | C46: =C9 | E46: -
A47: 2027 | B47: 보수 | C47: =C16*(1+C7/100) | E47: =C17/C16-1
A48: 2028 | B48: 보수 | C48: =C17*(1+C7/100) | E48: =C18/C17-1
A49: 2029 | B49: 보수 | C49: =C18*(1+C7/100) | E49: =C19/C18-1
A50: 2030 | B50: 보수 | C50: =C19*(1+C7/100) | E50: =C20/C19-1
A51: 2031 | B51: 보수 | C51: =C20*(1+C8/100) | E51: =C21/C20-1
A52: 2032 | B52: 보수 | C52: =C21*(1+C8/100) | E52: =C22/C21-1
A53: 2033 | B53: 보수 | C53: =C22*(1+C8/100) | E53: =C23/C22-1
A54: 2034 | B54: 보수 | C54: =C23*(1+C8/100) | E54: =C24/C23-1
A55: 2035 | B55: 보수 | C55: =C24*(1+C8/100) | E55: =C25/C24-1
A57: 2026 | B57: 기본 | C57: =D9 | E57: -
A58: 2027 | B58: 기본 | C58: =D26*(1+D7/100) | E58: =C27/C26-1
A59: 2028 | B59: 기본 | C59: =D27*(1+D7/100) | E59: =C28/C27-1
A60: 2029 | B60: 기본 | C60: =D28*(1+D7/100) | E60: =C29/C28-1
A61: 2030 | B61: 기본 | C61: =D29*(1+D7/100) | E61: =C30/C29-1
A62: 2031 | B62: 기본 | C62: =D30*(1+D8/100) | E62: =C31/C30-1
A63: 2032 | B63: 기본 | C63: =D31*(1+D8/100) | E63: =C32/C31-1
A64: 2033 | B64: 기본 | C64: =D32*(1+D8/100) | E64: =C33/C32-1
A65: 2034 | B65: 기본 | C65: =D33*(1+D8/100) | E65: =C34/C33-1
A66: 2035 | B66: 기본 | C66: =D34*(1+D8/100) | E66: =C35/C34-1
A68: 2026 | B68: 낙관 | C68: =E9 | E68: -
A69: 2027 | B69: 낙관 | C69: =E36*(1+E7/100) | E69: =C37/C36-1
A70: 2028 | B70: 낙관 | C70: =E37*(1+E7/100) | E70: =C38/C37-1
A71: 2029 | B71: 낙관 | C71: =E38*(1+E7/100) | E71: =C39/C38-1
A72: 2030 | B72: 낙관 | C72: =E39*(1+E7/100) | E72: =C40/C39-1
A73: 2031 | B73: 낙관 | C73: =E40*(1+E8/100) | E73: =C41/C40-1
A74: 2032 | B74: 낙관 | C74: =E41*(1+E8/100) | E74: =C42/C41-1
...

Sheet 요약대시보드
A1: B★ eCO₂ 소형 실용화 — Ch.1 요약 대시보드
A2: 기준일: 2026-03-15 | 한글판 v1.0 | B-1d 산출물
A4: 핵심 투자 KPI (기본 시나리오)
A5: IRR (내부수익률) | B5: 42.4% | C5: B★KPI시나리오!D 참조
A6: 투자회수기간 (Payback) | B6: 4년 | C6: 기본 시나리오
A7: 순현재가치 (NPV) | B7: $81.7M | C7: 10년 기준, WACC 10%
A8: 초기 CAPEX (Hub-S1) | B8: $18M | C8: 1호기 DC냉각 모듈
A9: 10년 누적 매출 | B9: $527M | C9: 기본 시나리오
A11: 응용처 우선순위 요약 (우선순위매트릭스 시트 참조)
A12: 순위 | B12: 응용처 | C12: 종합점수 | D12: KR시장($M) | E12: CAGR
A13: ★1 | B13: =우선순위매트릭스!B4 | C13: =우선순위매트릭스!K4 | D13: =우선순위매트릭스!I4 | E13: =우선순위매트릭스!J4
A14: ★2 | B14: =우선순위매트릭스!B5 | C14: =우선순위매트릭스!K5 | D14: =우선순위매트릭스!I5 | E14: =우선순위매트릭스!J5
A15: 3 | B15: =우선순위매트릭스!B6 | C15: =우선순위매트릭스!K6 | D15: =우선순위매트릭스!I6 | E15: =우선순위매트릭스!J6
A16: 4 | B16: =우선순위매트릭스!B7 | C16: =우선순위매트릭스!K7 | D16: =우선순위매트릭스!I7 | E16: =우선순위매트릭스!J7
A17: 5 | B17: =우선순위매트릭스!B8 | C17: =우선순위매트릭스!K8 | D17: =우선순위매트릭스!I8 | E17: =우선순위매트릭스!J8
A18: 6 | B18: =우선순위매트릭스!B9 | C18: =우선순위매트릭스!K9 | D18: =우선순위매트릭스!I9 | E18: =우선순위매트릭스!J9
A20: 목표시장 규모 전망 (시장성장모델 시트 참조)
A21: 응용처 | B21: 2026E ($M) | C21: 2030F ($M) | D21: 2035F ($M) | E21: CAGR
A22: =시장성장모델!A4 | B22: =시장성장모델!D4 | C22: =시장성장모델!H4 | D22: =시장성장모델!M4 | E22: =시장성장모델!C4
A23: =시장성장모델!A5 | B23: =시장성장모델!D5 | C23: =시장성장모델!H5 | D23: =시장성장모델!M5 | E23: =시장성장모델!C5
A24: =시장성장모델!A6 | B24: =시장성장모델!D6 | C24: =시장성장모델!H6 | D24: =시장성장모델!M6 | E24: =시장성장모델!C6
A25: =시장성장모델!A7 | B25: =시장성장모델!D7 | C25: =시장성장모델!H7 | D25: =시장성장모델!M7 | E25: =시장성장모델!C7
A26: =시장성장모델!A8 | B26: =시장성장모델!D8 | C26: =시장성장모델!H8 | D26: =시장성장모델!M8 | E26: =시장성장모델!C8
A27: =시장성장모델!A9 | B27: =시장성장모델!D9 | C27: =시장성장모델!H9 | D27: =시장성장모델!M9 | E27: =시장성장모델!C9
