Workbook

Sheet Cover
B2: B★ eCO₂ Compact Commercialization Strategy
B3: Chapter 1: Application Priority & Financial Model
B4: English Edition
B7: Date | D7: 2026-03-15
B8: Version | D8: v1.0 (B-1d)
B9: Classification | D9: Confidential
B10: Author | D10: B★ Project Team
B11: Base Year | D11: 2026
B14: Sheet Contents
B16: ① | C16: EvalCriteria | D16: 5 evaluation criteria & weights — auto-calculated weighted score
B17: ② | C17: PriorityMatrix | D17: 6 applications × 5 criteria scoring — formula-driven composite score
B18: ③ | C18: MarketGrowth | D18: 6 applications × 2026-2035 CAGR compound growth formulas
B19: ④ | C19: KPI_Scenario | D19: Conservative/Base/Optimistic 3-scenario — NPV, IRR, Payback formulas
B20: ⑤ | C20: Dashboard | D20: Key metrics auto-referenced summary
B23: Key Investment Figures
B25: IRR: 42.4% | C25: Payback: 4 Years | D25: NPV: $81.7M
B26: CAPEX: $18M | C26: 10-yr Revenue: $527M

Sheet EvalCriteria
A1: Criterion ID | B1: Name | C1: Weight (%) | D1: Description | E1: Notes
A2: C1 | B2: Revenue Speed | C2: 25 | D2: Speed of revenue realization and contract pipeline clarity (1-10) | E2: Higher = faster revenue
A3: C2 | B3: Tech Fitness | C3: 20 | D3: eCO₂ technology fitness and TRL level for the application (1-10) | E3: TRL 7+ = score ≥9
A4: C3 | B4: B★ Tech Fit | C4: 20 | D4: Alignment with B★ eCO₂ compact module architecture (1-10) | E4: Core architecture match = 10
A5: C4 | B5: Policy Support | C5: 20 | D5: Korean gov't policy, licensing, and subsidy intensity (1-10) | E5: SMR Act / DC policy = high
A6: C5 | B6: CAGR Norm. | C6: 15 | D6: Market CAGR normalized score (CAGR 20%=10pts baseline) | E6: Linear interpolation
A7: Total | B7: — | C7: =SUM(C2:C6) | D7: Weight sum = 100%
A9: CAGR Normalization Reference Table
A10: CAGR Range | B10: Normalized Score | C10: Calculation Method
A11: ≥20% | B11: 10 pts | C11: Benchmark (DC Cooling 20.4%)
A12: 15% | B12: 8 pts | C12: Linear interpolation
A13: 10% | B13: 6 pts | C13: Linear interpolation
A14: 7% | B14: 5 pts | C14: Linear interpolation
A15: 5% | B15: 4 pts | C15: Minimum

Sheet PriorityMatrix
A1: Weight (ref.) | C1: 25% | D1: 20% | E1: 20% | F1: 20% | G1: 15%
C2: 0.25 | D2: 0.2 | E2: 0.2 | F2: 0.2 | G2: 0.15
A3: Rank | B3: Application | C3: Revenue Speed (25%) | D3: Tech Fitness (20%) | E3: B★ Tech Fit (20%) | F3: Policy Support (20%) | G3: CAGR Norm. (15%) | H3: Weighted Score (formula) | I3: KR Market ($M) | J3: CAGR (%) | K3: Composite Score | L3: B★ Strategy
A4: ★1 | B4: Data Center Cooling & WHR | C4: 9.5 | D4: 9.8 | E4: 9.8 | F4: 9.2 | G4: 9.3 | H4: =C4*$C$2+D4*$D$2+E4*$E$2+F4*$F$2+G4*$G$2 | I4: 19900 | J4: 0.204 | K4: 9.35 | L4: Execute Now (2026H2)
A5: ★2 | B5: Nuclear / SMR Cogeneration | C5: 8.2 | D5: 8.5 | E5: 8.8 | F5: 9 | G5: 8.7 | H5: =C5*$C$2+D5*$D$2+E5*$E$2+F5*$F$2+G5*$G$2 | I5: 4500 | J5: 0.18 | K5: 8.42 | L5: Mid-term Core (2028+)
A6: 3 | B6: LNG Power Waste Heat | C6: 7.5 | D6: 7.2 | E6: 7 | F6: 7.8 | G6: 6.2 | H6: =C6*$C$2+D6*$D$2+E6*$E$2+F6*$F$2+G6*$G$2 | I6: 3800 | J6: 0.085 | K6: 7.18 | L6: Mid-term Pipeline
A7: 4 | B7: Industrial Heat Pumps | C7: 6.8 | D7: 7 | E7: 6.5 | F7: 7.5 | G7: 5.8 | H7: =C7*$C$2+D7*$D$2+E7*$E$2+F7*$F$2+G7*$G$2 | I7: 8000 | J7: 0.079 | K7: 6.73 | L7: Policy-Linked R&D
A8: 5 | B8: Thermal Power WHR | C8: 6 | D8: 6.5 | E8: 6.2 | F8: 6.8 | G8: 5.2 | H8: =C8*$C$2+D8*$D$2+E8*$E$2+F8*$F$2+G8*$G$2 | I8: 3000 | J8: 0.065 | K8: 6.18 | L8: Monitor Transition
A9: 6 | B9: Blast Furnace WHR | C9: 5.5 | D9: 6 | E9: 5.8 | F9: 6.2 | G9: 4.8 | H9: =C9*$C$2+D9*$D$2+E9*$E$2+F9*$F$2+G9*$G$2 | I9: 2200 | J9: 0.06 | K9: 5.29 | L9: Long-term R&D (2030+)
A11: Stats | C11: MAX | D11: MAX | E11: MAX | F11: MAX | G11: MAX | H11: MAX | I11: MAX | J11: MAX | K11: MAX
B12: Max | C12: =MAX(C4:C9) | D12: =MAX(D4:D9) | E12: =MAX(E4:E9) | F12: =MAX(F4:F9) | G12: =MAX(G4:G9) | H12: =MAX(H4:H9) | I12: =MAX(I4:I9) | J12: =MAX(J4:J9) | K12: =MAX(K4:K9)
B13: Average | C13: =AVERAGE(C4:C9) | D13: =AVERAGE(D4:D9) | E13: =AVERAGE(E4:E9) | F13: =AVERAGE(F4:F9) | G13: =AVERAGE(G4:G9) | H13: =AVERAGE(H4:H9) | I13: =AVERAGE(I4:I9) | J13: =AVERAGE(J4:J9) | K13: =AVERAGE(K4:K9)

Sheet MarketGrowth
A1: Korea Target Market Growth Model (2026-2035) ※ CAGR Compound Growth Formulas Applied
A2: Unit: $M | Growth formula: Base Year × (1+CAGR)^(Year-2026)
A3: Application | B3: 2026E Base ($M) | C3: CAGR(%) | D3: 2026F | E3: 2027F | F3: 2028F | G3: 2029F | H3: 2030F | I3: 2031F | J3: 2032F | K3: 2033F | L3: 2034F | M3: 2035F | N3: 10yr CAGR Check
A4: Data Center Cooling & WHR | B4: 1990 | C4: 0.204 | D4: =B4 | E4: =$B4*(1+$C4)^1 | F4: =$B4*(1+$C4)^2 | G4: =$B4*(1+$C4)^3 | H4: =$B4*(1+$C4)^4 | I4: =$B4*(1+$C4)^5 | J4: =$B4*(1+$C4)^6 | K4: =$B4*(1+$C4)^7 | L4: =$B4*(1+$C4)^8 | M4: =$B4*(1+$C4)^9 | N4: =(M4/D4)^(1/9)-1
A5: Nuclear / SMR Cogeneration | B5: 380 | C5: 0.18 | D5: =B5 | E5: =$B5*(1+$C5)^1 | F5: =$B5*(1+$C5)^2 | G5: =$B5*(1+$C5)^3 | H5: =$B5*(1+$C5)^4 | I5: =$B5*(1+$C5)^5 | J5: =$B5*(1+$C5)^6 | K5: =$B5*(1+$C5)^7 | L5: =$B5*(1+$C5)^8 | M5: =$B5*(1+$C5)^9 | N5: =(M5/D5)^(1/9)-1
A6: LNG Power Waste Heat | B6: 342 | C6: 0.085 | D6: =B6 | E6: =$B6*(1+$C6)^1 | F6: =$B6*(1+$C6)^2 | G6: =$B6*(1+$C6)^3 | H6: =$B6*(1+$C6)^4 | I6: =$B6*(1+$C6)^5 | J6: =$B6*(1+$C6)^6 | K6: =$B6*(1+$C6)^7 | L6: =$B6*(1+$C6)^8 | M6: =$B6*(1+$C6)^9 | N6: =(M6/D6)^(1/9)-1
A7: Industrial Heat Pumps | B7: 3430 | C7: 0.079 | D7: =B7 | E7: =$B7*(1+$C7)^1 | F7: =$B7*(1+$C7)^2 | G7: =$B7*(1+$C7)^3 | H7: =$B7*(1+$C7)^4 | I7: =$B7*(1+$C7)^5 | J7: =$B7*(1+$C7)^6 | K7: =$B7*(1+$C7)^7 | L7: =$B7*(1+$C7)^8 | M7: =$B7*(1+$C7)^9 | N7: =(M7/D7)^(1/9)-1
A8: Thermal Power WHR | B8: 290 | C8: 0.065 | D8: =B8 | E8: =$B8*(1+$C8)^1 | F8: =$B8*(1+$C8)^2 | G8: =$B8*(1+$C8)^3 | H8: =$B8*(1+$C8)^4 | I8: =$B8*(1+$C8)^5 | J8: =$B8*(1+$C8)^6 | K8: =$B8*(1+$C8)^7 | L8: =$B8*(1+$C8)^8 | M8: =$B8*(1+$C8)^9 | N8: =(M8/D8)^(1/9)-1
A9: Blast Furnace WHR | B9: 215 | C9: 0.06 | D9: =B9 | E9: =$B9*(1+$C9)^1 | F9: =$B9*(1+$C9)^2 | G9: =$B9*(1+$C9)^3 | H9: =$B9*(1+$C9)^4 | I9: =$B9*(1+$C9)^5 | J9: =$B9*(1+$C9)^6 | K9: =$B9*(1+$C9)^7 | L9: =$B9*(1+$C9)^8 | M9: =$B9*(1+$C9)^9 | N9: =(M9/D9)^(1/9)-1
A10: Total (TAM) | B10: =SUM(B4:B9) | D10: =SUM(D4:D9) | E10: =SUM(E4:E9) | F10: =SUM(F4:F9) | G10: =SUM(G4:G9) | H10: =SUM(H4:H9) | I10: =SUM(I4:I9) | J10: =SUM(J4:J9) | K10: =SUM(K4:K9) | ... M10: =SUM(M4:M9)
A12: B★ SAM Estimate (DC Cooling Market Share-Based)
A13: Scenario | B13: Share Assumption | C13: CAGR | D13: 2026F | E13: 2027F | F13: 2028F | G13: 2029F | H13: 2030F | I13: 2031F | J13: 2032F | K13: 2033F | L13: 2034F | M13: 2035F | N13: Notes
A14: Conservative SAM (3% share) | B14: 0.03 | D14: =D4*0.03 | E14: =E4*0.03 | F14: =F4*0.03 | G14: =G4*0.03 | H14: =H4*0.03 | I14: =I4*0.03 | J14: =J4*0.03 | K14: =K4*0.03 | ... M14: =M4*0.03 | N14: Hub-S1 Revenue Estimate
A15: Base SAM (6% share) | B15: 0.06 | D15: =D4*0.06 | E15: =E4*0.06 | F15: =F4*0.06 | G15: =G4*0.06 | H15: =H4*0.06 | I15: =I4*0.06 | J15: =J4*0.06 | K15: =K4*0.06 | ... M15: =M4*0.06 | N15: Hub-S1 Revenue Estimate
A16: Optimistic SAM (10% share) | B16: 0.1 | D16: =D4*0.1 | E16: =E4*0.1 | F16: =F4*0.1 | G16: =G4*0.1 | H16: =H4*0.1 | I16: =I4*0.1 | J16: =J4*0.1 | K16: =K4*0.1 | ... M16: =M4*0.1 | N16: Hub-S1 Revenue Estimate

Sheet KPI_Scenario
A1: B★ eCO₂ Hub-S1 KPI Scenario Analysis (2026-2035)
A3: [ Investment Assumptions — Input Values (Edit yellow cells directly) ]
A4: Item | B4: Unit | C4: Conservative | D4: Base | E4: Optimistic | F4: Notes
A5: Initial CAPEX (Hub-S1) | B5: $M | C5: 18 | D5: 18 | E5: 18 | F5: Unit 1 DC cooling module — fixed
A6: Annual OPEX | B6: $M/yr | C6: 1.8 | D6: 1.5 | E6: 1.2 | F6: CAPEX 10%/8%/7%
A7: Revenue Growth Rate (Yr 1-5) | B7: % | C7: 25 | D7: 35 | E7: 50 | F7: DC cooling pipeline ramp
A8: Revenue Growth Rate (Yr 6-10) | B8: % | C8: 15 | D8: 22 | E8: 35 | F8: SMR + LNG pipeline addition
A9: Base Revenue (2026) | B9: $M | C9: 8 | D9: 12 | E9: 18 | F9: Based on PoC contract count
A10: Discount Rate (WACC) | B10: % | C10: 12 | D10: 10 | E10: 8 | F10: B★ risk premium
A11: Corporate Tax Rate | B11: % | C11: 25 | D11: 22 | E11: 20 | F11: Korea corporate tax basis
A12: Terminal Value (Year 10) | B12: $M | C12: 30 | D12: 45 | E12: 60 | F12: Technology + customer asset
A14: [ Annual Revenue Estimates ($M) — Formula-Driven ]
A15: Year | B15: Scenario | C15: Revenue ($M) | D15: Cumul. Revenue ($M) | E15: YoY Growth | F15: Notes
A16: 2026 | B16: Conservative | C16: =C9 | E16: -
A17: 2027 | B17: Conservative | C17: =C16*(1+C7/100) | E17: =C17/C16-1
A18: 2028 | B18: Conservative | C18: =C17*(1+C7/100) | E18: =C18/C17-1
A19: 2029 | B19: Conservative | C19: =C18*(1+C7/100) | E19: =C19/C18-1
A20: 2030 | B20: Conservative | C20: =C19*(1+C7/100) | E20: =C20/C19-1
A21: 2031 | B21: Conservative | C21: =C20*(1+C8/100) | E21: =C21/C20-1
A22: 2032 | B22: Conservative | C22: =C21*(1+C8/100) | E22: =C22/C21-1
A23: 2033 | B23: Conservative | C23: =C22*(1+C8/100) | E23: =C23/C22-1
A24: 2034 | B24: Conservative | C24: =C23*(1+C8/100) | E24: =C24/C23-1
A25: 2035 | B25: Conservative | C25: =C24*(1+C8/100) | E25: =C25/C24-1
A27: 2026 | B27: Base | C27: =D9 | E27: -
A28: 2027 | B28: Base | C28: =D26*(1+D7/100) | E28: =C27/C26-1
A29: 2028 | B29: Base | C29: =D27*(1+D7/100) | E29: =C28/C27-1
A30: 2029 | B30: Base | C30: =D28*(1+D7/100) | E30: =C29/C28-1
A31: 2030 | B31: Base | C31: =D29*(1+D7/100) | E31: =C30/C29-1
A32: 2031 | B32: Base | C32: =D30*(1+D8/100) | E32: =C31/C30-1
A33: 2032 | B33: Base | C33: =D31*(1+D8/100) | E33: =C32/C31-1
A34: 2033 | B34: Base | C34: =D32*(1+D8/100) | E34: =C33/C32-1
A35: 2034 | B35: Base | C35: =D33*(1+D8/100) | E35: =C34/C33-1
A36: 2035 | B36: Base | C36: =D34*(1+D8/100) | E36: =C35/C34-1
A38: 2026 | B38: Optimistic | C38: =E9 | E38: -
A39: 2027 | B39: Optimistic | C39: =E36*(1+E7/100) | E39: =C37/C36-1
A40: 2028 | B40: Optimistic | C40: =E37*(1+E7/100) | E40: =C38/C37-1
A41: 2029 | B41: Optimistic | C41: =E38*(1+E7/100) | E41: =C39/C38-1
A42: 2030 | B42: Optimistic | C42: =E39*(1+E7/100) | E42: =C40/C39-1
A43: 2031 | B43: Optimistic | C43: =E40*(1+E8/100) | E43: =C41/C40-1
A44: 2032 | B44: Optimistic | C44: =E41*(1+E8/100) | E44: =C42/C41-1
...

Sheet Dashboard
A1: B★ eCO₂ Compact Strategy — Ch.1 Summary Dashboard
A2: Date: 2026-03-15 | English Edition v1.0 | B-1d Output
A4: Key Investment KPIs (Base Scenario)
A5: Internal Rate of Return (IRR) | B5: 42.4% | C5: KPI_Scenario Sheet Ref.
A6: Payback Period | B6: 4 Years | C6: Base Scenario
A7: Net Present Value (NPV) | B7: $81.7M | C7: 10-year, WACC 10%
A8: Initial CAPEX (Hub-S1) | B8: $18M | C8: Unit 1 DC Cooling Module
A9: 10-Year Cumulative Revenue | B9: $527M | C9: Base Scenario
A11: Application Priority Summary (→ PriorityMatrix Sheet)
A12: Rank | B12: Application | C12: Score | D12: KR Market ($M) | E12: CAGR
A13: ★1 | B13: =PriorityMatrix!B4 | C13: =PriorityMatrix!K4 | D13: =PriorityMatrix!I4 | E13: =PriorityMatrix!J4
A14: ★2 | B14: =PriorityMatrix!B5 | C14: =PriorityMatrix!K5 | D14: =PriorityMatrix!I5 | E14: =PriorityMatrix!J5
A15: 3 | B15: =PriorityMatrix!B6 | C15: =PriorityMatrix!K6 | D15: =PriorityMatrix!I6 | E15: =PriorityMatrix!J6
A16: 4 | B16: =PriorityMatrix!B7 | C16: =PriorityMatrix!K7 | D16: =PriorityMatrix!I7 | E16: =PriorityMatrix!J7
A17: 5 | B17: =PriorityMatrix!B8 | C17: =PriorityMatrix!K8 | D17: =PriorityMatrix!I8 | E17: =PriorityMatrix!J8
A18: 6 | B18: =PriorityMatrix!B9 | C18: =PriorityMatrix!K9 | D18: =PriorityMatrix!I9 | E18: =PriorityMatrix!J9
A20: Target Market Size Forecast (→ MarketGrowth Sheet)
A21: Application | B21: 2026E ($M) | C21: 2030F ($M) | D21: 2035F ($M) | E21: CAGR
A22: =MarketGrowth!A4 | B22: =MarketGrowth!D4 | C22: =MarketGrowth!H4 | D22: =MarketGrowth!M4 | E22: =MarketGrowth!C4
A23: =MarketGrowth!A5 | B23: =MarketGrowth!D5 | C23: =MarketGrowth!H5 | D23: =MarketGrowth!M5 | E23: =MarketGrowth!C5
A24: =MarketGrowth!A6 | B24: =MarketGrowth!D6 | C24: =MarketGrowth!H6 | D24: =MarketGrowth!M6 | E24: =MarketGrowth!C6
A25: =MarketGrowth!A7 | B25: =MarketGrowth!D7 | C25: =MarketGrowth!H7 | D25: =MarketGrowth!M7 | E25: =MarketGrowth!C7
A26: =MarketGrowth!A8 | B26: =MarketGrowth!D8 | C26: =MarketGrowth!H8 | D26: =MarketGrowth!M8 | E26: =MarketGrowth!C8
A27: =MarketGrowth!A9 | B27: =MarketGrowth!D9 | C27: =MarketGrowth!H9 | D27: =MarketGrowth!M9 | E27: =MarketGrowth!C9
